Workbook

Sheet Benchmark_URLs
A1: url_id | B1: category | C1: subcategory | D1: url | E1: domain | F1: expected_content_type | G1: expected_js_required | H1: expected_tables | I1: expected_pagination | J1: expected_date_present | K1: expected_min_chars | L1: notes
A2: U001 | B2: Static_HTML | C2: Regulator overview | D2: https://www.federalreserve.gov/supervisionreg.htm | E2: www.federalreserve.gov | F2: html | G2: N | H2: N | I2: N | J2: Y | K2: 4000 | L2: Fed supervision & regulation hub; good main-content test
A3: U002 | B3: Static_HTML | C3: Manual index | D3: https://www.occ.treas.gov/publications-and-resources/publications/comptrollers-handbook/index-comptrollers-handbook.html | E3: www.occ.treas.gov | F3: html | G3: N | H3: N | I3: N | J3: Y | K3: 3000 | L3: OCC handbook index; headings + link lists
A4: U003 | B4: Static_HTML | C4: Manual hub | D4: https://www.fdic.gov/bank-examinations/examination-manuals | E4: www.fdic.gov | F4: html | G4: N | H4: N | I4: N | J4: Y | K4: 2000 | L4: FDIC examination manuals hub
A5: U004 | B5: Table_Heavy | C5: Regulatory datasets | D5: https://www.sec.gov/data-research/sec-markets-data/form-n-port-data-sets | E5: www.sec.gov | F5: html | G5: N | H5: Y | I5: N | J5: Y | K5: 2000 | L5: SEC datasets page with tables/links
A6: U005 | B6: Static_HTML | C6: Standards hub | D6: https://www.bis.org/baselframework/ | E6: www.bis.org | F6: html | G6: N | H6: N | I6: N | J6: Y | K6: 2000 | L6: BIS Basel Framework hub
A7: U006 | B7: Static_HTML | C7: Industry association | D7: https://www.ici.org/ | E7: www.ici.org | F7: html | G7: Y | H7: N | I7: N | J7: Y | K7: 1500 | L7: ICI site (may use JS); tests navigation noise
A8: U007 | B8: Static_HTML | C8: Research hub | D8: https://www.cfainstitute.org/en/research | E8: www.cfainstitute.org | F8: html | G8: Y | H8: N | I8: N | J8: Y | K8: 2000 | L8: CFA Institute research landing; structured sections
A9: U008 | B9: Pagination | C9: Regulator listings | D9: https://www.federalreserve.gov/newsevents/pressreleases.htm | E9: www.federalreserve.gov | F9: html | G9: N | H9: N | I9: Y | J9: Y | K9: 2000 | L9: Fed press releases listing (year links)
A10: U009 | B10: Pagination | C10: Regulator listings | D10: https://www.federalreserve.gov/newsevents/pressreleases/2025-press.htm | E10: www.federalreserve.gov | F10: html | G10: N | H10: N | I10: Y | J10: Y | K10: 2000 | L10: Fed 2025 press release list; long page
A11: U010 | B11: Pagination | C11: Regulator listings | D11: https://www.sec.gov/newsroom/press-releases?page=0 | E11: www.sec.gov | F11: html | G11: N | H11: Y | I11: Y | J11: Y | K11: 2000 | L11: SEC press releases page 0; pagination param
A12: U011 | B12: Pagination | C12: Regulator listings | D12: https://www.sec.gov/newsroom/press-releases?page=2 | E12: www.sec.gov | F12: html | G12: N | H12: Y | I12: Y | J12: Y | K12: 2000 | L12: SEC press releases page 2; pagination param
A13: U012 | B13: Table_Heavy | C13: Data portal | D13: https://fred.stlouisfed.org/series/GDP | E13: fred.stlouisfed.org | F13: html | G13: Y | H13: Y | I13: N | J13: Y | K13: 2500 | L13: FRED series page with chart + data table
... A46: U045 | B46: Static_HTML | C46: IMF press briefing | D46: https://www.imf.org/en/news/articles/2025/12/23/tr-12232025-sri-lanka-press-briefing-on-imf-approval-for-request-for-rapid-financing-instrument | E46: www.imf.org | F46: html | G46: N | H46: N | I46: N | J46: Y | K46: 2500 | L46: IMF article; long transcript; good text extraction

Sheet Crawl_Results
A1: run_id | B1: run_date | C1: tool | D1: prompt_id | E1: url_id | F1: url | G1: final_url | H1: expected_content_type | I1: expected_js_required | J1: expected_tables | K1: expected_pagination | L1: expected_date_present | M1: expected_min_chars | N1: http_status | O1: fetch_success_1_0 | P1: js_rendered_1_0 | Q1: main_content_chars (~ approx) | R1: full_content_chars | S1: noise_chars | T1: title_present_1_0 | U1: date_present_1_0 | V1: author_present_1_0 | W1: outbound_links_count | X1: pdf_pages_parsed | Y1: latency_seconds | Z1: credits_used | AA1: error_type | AB1: notes | AC1: noise_estimate | AD1: meta_hit_rate | AE1: content_ok_1_0 | AF1: pdf_ok_1_0 | AG1: js_ok_1_0 | AH1: quality_score | AI1: efficiency_score | AJ1: quality_score_reasons
A2: 163901032026 | B2: 46025 | C2: Serper | D2: Static_HTML | E2: U001 | F2: =IF($E2="","",VLOOKUP($E2,Benchmark_URLs!$A$2:$L$46,4,FALSE)) -> https://www.federalreserve.gov/supervisionreg.htm | H2: =IF($E2="","",VLOOKUP($E2,Benchmark_URLs!$A$2:$L$46,6,FALSE)) -> html | I2: =IF($E2="","",VLOOKUP($E2,Benchmark_URLs!$A$2:$L$46,7,FALSE)) -> N | J2: =IF($E2="","",VLOOKUP($E2,Benchmark_URLs!$A$2:$L$46,8,FALSE)) -> N | K2: =IF($E2="","",VLOOKUP($E2,Benchmark_URLs!$A$2:$L$46,9,FALSE)) -> N | L2: =IF($E2="","",VLOOKUP($E2,Benchmark_URLs!$A$2:$L$46,10,FALSE)) -> Y | M2: =IF($E2="","",VLOOKUP($E2,Benchmark_URLs!$A$2:$L$46,11,FALSE)) -> 4000 | N2: 200 | O2: 1 | P2: 0 | Q2: 1590 | R2: 1590 | S2: 0 | T2: 1 | U2: 1 | V2: 0 | W2: 0 | Y2: 0.3 | Z2: 2 | AC2: 1 | AD2: =IF($E2="","",IFERROR(AVERAGE($T2,IF($L2="Y",$U2,1),$V2),"")) -> 0.66666667 | AE2: =IF($E2="","",IFERROR(IF($Q2>=$M2,1,0),0)) -> 0 | AF2: =IF($E2="","",IF($H2="pdf",IFERROR(IF($X2>=Weights!$B$10,1,0),0),1)) -> 1 | AG2: =IF($E2="","",IF($I2="Y",IFERROR($P2,0),1)) -> 1 | AH2: =IF($E2="","",IFERROR((Weights!$B$2*$O2 + Weights!$B$3*$AE2 + Weights!$B$4*$AD2 + Weights!$B$5*(1-$AC2) + Weights!$B$6*$AF2 + Weights!$B$7*$AG2)/SUM(Weights!$B$2:$B$7),"" )) -> 0.55 | AI2: =IF($E2="","",IF($O2=0,0,IFERROR($AH2/MAX(Weights!$B$8,$Y2)/MAX(Weights!$B$9,IF($Z2="",0,$Z2)), ""))) -> 0.91666667
A3: 170801032026 | B3: 46025 | C3: Serper | D3: Static_HTML | E3: U002 | F3: =IF($E3="","",VLOOKUP($E3,Benchmark_URLs!$A$2:$L$46,4,FALSE)) -> https://www.occ.treas.gov/publications-and-resources/publications/comptrollers-handbook/index-comptrollers-handbook.html | H3: =IF($E3="","",VLOOKUP($E3,Benchmark_URLs!$A$2:$L$46,6,FALSE)) -> html | I3: =IF($E3="","",VLOOKUP($E3,Benchmark_URLs!$A$2:$L$46,7,FALSE)) -> N | J3: =IF($E3="","",VLOOKUP($E3,Benchmark_URLs!$A$2:$L$46,8,FALSE)) -> N | K3: =IF($E3="","",VLOOKUP($E3,Benchmark_URLs!$A$2:$L$46,9,FALSE)) -> N | L3: =IF($E3="","",VLOOKUP($E3,Benchmark_URLs!$A$2:$L$46,10,FALSE)) -> Y | M3: =IF($E3="","",VLOOKUP($E3,Benchmark_URLs!$A$2:$L$46,11,FALSE)) -> 3000 | N3: 200 | O3: 1 | P3: 0 | Q3: 7502 | R3: 7502 | S3: 0 | T3: 1 | U3: 1 | V3: 0 | W3: 0 | Y3: 0.3 | Z3: 2 | AC3: 1 | AD3: =IF($E3="","",IFERROR(AVERAGE($T3,IF($L3="Y",$U3,1),$V3),"")) -> 0.66666667 | AE3: =IF($E3="","",IFERROR(IF($Q3>=$M3,1,0),0)) -> 1 | AF3: =IF($E3="","",IF($H3="pdf",IFERROR(IF($X3>=Weights!$B$10,1,0),0),1)) -> 1 | AG3: =IF($E3="","",IF($I3="Y",IFERROR($P3,0),1)) -> 1 | AH3: =IF($E3="","",IFERROR((Weights!$B$2*$O3 + Weights!$B$3*$AE3 + Weights!$B$4*$AD3 + Weights!$B$5*(1-$AC3) + Weights!$B$6*$AF3 + Weights!$B$7*$AG3)/SUM(Weights!$B$2:$B$7),"" )) -> 0.8 | AI3: =IF($E3="","",IF($O3=0,0,IFERROR($AH3/MAX(Weights!$B$8,$Y3)/MAX(Weights!$B$9,IF($Z3="",0,$Z3)), ""))) -> 1.3333333
A4: 171401032026 | B4: 46025 | C4: Serper | D4: Static_HTML | E4: U003 | F4: =IF($E4="","",VLOOKUP($E4,Benchmark_URLs!$A$2:$L$46,4,FALSE)) -> https://www.fdic.gov/bank-examinations/examination-manuals | H4: =IF($E4="","",VLOOKUP($E4,Benchmark_URLs!$A$2:$L$46,6,FALSE)) -> html | I4: =IF($E4="","",VLOOKUP($E4,Benchmark_URLs!$A$2:$L$46,7,FALSE)) -> N | J4: =IF($E4="","",VLOOKUP($E4,Benchmark_URLs!$A$2:$L$46,8,FALSE)) -> N | K4: =IF($E4="","",VLOOKUP($E4,Benchmark_URLs!$A$2:$L$46,9,FALSE)) -> N | L4: =IF($E4="","",VLOOKUP($E4,Benchmark_URLs!$A$2:$L$46,10,FALSE)) -> Y | M4: =IF($E4="","",VLOOKUP($E4,Benchmark_URLs!$A$2:$L$46,11,FALSE)) -> 2000 | N4: 200 | O4: 1 | P4: 0 | Q4: 1400 | R4: 1400 | S4: 0 | T4: 1 | U4: 1 | V4: 0 | W4: 0 | Y4: 0.475 | Z4: 2 | AC4: 1 | AD4: =IF($E4="","",IFERROR(AVERAGE($T4,IF($L4="Y",$U4,1),$V4),"")) -> 0.66666667 | AE4: =IF($E4="","",IFERROR(IF($Q4>=$M4,1,0),0)) -> 0 | AF4: =IF($E4="","",IF($H4="pdf",IFERROR(IF($X4>=Weights!$B$10,1,0),0),1)) -> 1 | AG4: =IF($E4="","",IF($I4="Y",IFERROR($P4,0),1)) -> 1 | AH4: =IF($E4="","",IFERROR((Weights!$B$2*$O4 + Weights!$B$3*$AE4 + Weights!$B$4*$AD4 + Weights!$B$5*(1-$AC4) + Weights!$B$6*$AF4 + Weights!$B$7*$AG4)/SUM(Weights!$B$2:$B$7),"" )) -> 0.55 | AI4: =IF($E4="","",IF($O4=0,0,IFERROR($AH4/MAX(Weights!$B$8,$Y4)/MAX(Weights!$B$9,IF($Z4="",0,$Z4)), ""))) -> 0.57894737
A5: 172101032026 | B5: 46025 | C5: Serper | D5: Table_Heavy | E5: U004 | F5: =IF($E5="","",VLOOKUP($E5,Benchmark_URLs!$A$2:$L$46,4,FALSE)) -> https://www.sec.gov/data-research/sec-markets-data/form-n-port-data-sets | H5: =IF($E5="","",VLOOKUP($E5,Benchmark_URLs!$A$2:$L$46,6,FALSE)) -> html | I5: =IF($E5="","",VLOOKUP($E5,Benchmark_URLs!$A$2:$L$46,7,FALSE)) -> N | J5: =IF($E5="","",VLOOKUP($E5,Benchmark_URLs!$A$2:$L$46,8,FALSE)) -> Y | K5: =IF($E5="","",VLOOKUP($E5,Benchmark_URLs!$A$2:$L$46,9,FALSE)) -> N | L5: =IF($E5="","",VLOOKUP($E5,Benchmark_URLs!$A$2:$L$46,10,FALSE)) -> Y | M5: =IF($E5="","",VLOOKUP($E5,Benchmark_URLs!$A$2:$L$46,11,FALSE)) -> 2000 | N5: 200 | O5: 1 | P5: 0 | Q5: 2200 | R5: 2200 | S5: 0 | T5: 1 | U5: 1 | V5: 0 | W5: 0 | Y5: 0.889 | Z5: 2 | AC5: 1 | AD5: =IF($E5="","",IFERROR(AVERAGE($T5,IF($L5="Y",$U5,1),$V5),"")) -> 0.66666667 | AE5: =IF($E5="","",IFERROR(IF($Q5>=$M5,1,0),0)) -> 1 | AF5: =IF($E5="","",IF($H5="pdf",IFERROR(IF($X5>=Weights!$B$10,1,0),0),1)) -> 1 | AG5: =IF($E5="","",IF($I5="Y",IFERROR($P5,0),1)) -> 1 | AH5: =IF($E5="","",IFERROR((Weights!$B$2*$O5 + Weights!$B$3*$AE5 + Weights!$B$4*$AD5 + Weights!$B$5*(1-$AC5) + Weights!$B$6*$AF5 + Weights!$B$7*$AG5)/SUM(Weights!$B$2:$B$7),"" )) -> 0.8 | AI5: =IF($E5="","",IF($O5=0,0,IFERROR($AH5/MAX(Weights!$B$8,$Y5)/MAX(Weights!$B$9,IF($Z5="",0,$Z5)), ""))) -> 0.44994376
A6: 172601032026 | B6: 46025 | C6: Serper | D6: Table_Heavy | E6: U012 | F6: =IF($E6="","",VLOOKUP($E6,Benchmark_URLs!$A$2:$L$46,4,FALSE)) -> https://fred.stlouisfed.org/series/GDP | H6: =IF($E6="","",VLOOKUP($E6,Benchmark_URLs!$A$2:$L$46,6,FALSE)) -> html | I6: =IF($E6="","",VLOOKUP($E6,Benchmark_URLs!$A$2:$L$46,7,FALSE)) -> Y | J6: =IF($E6="","",VLOOKUP($E6,Benchmark_URLs!$A$2:$L$46,8,FALSE)) -> Y | K6: =IF($E6="","",VLOOKUP($E6,Benchmark_URLs!$A$2:$L$46,9,FALSE)) -> N | L6: =IF($E6="","",VLOOKUP($E6,Benchmark_URLs!$A$2:$L$46,10,FALSE)) -> Y | M6: =IF($E6="","",VLOOKUP($E6,Benchmark_URLs!$A$2:$L$46,11,FALSE)) -> 2500 | N6: 200 | O6: 1 | P6: 0 | Q6: 1100 | R6: 1100 | S6: 0 | T6: 1 | U6: 0 | V6: 0 | W6: 0 | Y6: 1.125 | Z6: 2 | AC6: 1 | AD6: =IF($E6="","",IFERROR(AVERAGE($T6,IF($L6="Y",$U6,1),$V6),"")) -> 0.33333333 | AE6: =IF($E6="","",IFERROR(IF($Q6>=$M6,1,0),0)) -> 0 | AF6: =IF($E6="","",IF($H6="pdf",IFERROR(IF($X6>=Weights!$B$10,1,0),0),1)) -> 1 | AG6: =IF($E6="","",IF($I6="Y",IFERROR($P6,0),1)) -> 0 | AH6: =IF($E6="","",IFERROR((Weights!$B$2*$O6 + Weights!$B$3*$AE6 + Weights!$B$4*$AD6 + Weights!$B$5*(1-$AC6) + Weights!$B$6*$AF6 + Weights!$B$7*$AG6)/SUM(Weights!$B$2:$B$7),"" )) -> 0.45 | AI6: =IF($E6="","",IF($O6=0,0,IFERROR($AH6/MAX(Weights!$B$8,$Y6)/MAX(Weights!$B$9,IF($Z6="",0,$Z6)), ""))) -> 0.2
A7: 175901032026 | B7: 46025 | C7: Serper | D7: Pagination | E7: U008 | F7: =IF($E7="","",VLOOKUP($E7,Benchmark_URLs!$A$2:$L$46,4,FALSE)) -> https://www.federalreserve.gov/newsevents/pressreleases.htm | H7: =IF($E7="","",VLOOKUP($E7,Benchmark_URLs!$A$2:$L$46,6,FALSE)) -> html | I7: =IF($E7="","",VLOOKUP($E7,Benchmark_URLs!$A$2:$L$46,7,FALSE)) -> N | J7: =IF($E7="","",VLOOKUP($E7,Benchmark_URLs!$A$2:$L$46,8,FALSE)) -> N | K7: =IF($E7="","",VLOOKUP($E7,Benchmark_URLs!$A$2:$L$46,9,FALSE)) -> Y | L7: =IF($E7="","",VLOOKUP($E7,Benchmark_URLs!$A$2:$L$46,10,FALSE)) -> Y | M7: =IF($E7="","",VLOOKUP($E7,Benchmark_URLs!$A$2:$L$46,11,FALSE)) -> 2000 | N7: 200 | O7: 1 | P7: 0 | Q7: 217 | R7: 217 | S7: 0 | T7: 1 | U7: 0 | V7: 0 | W7: 0 | Y7: 1.265 | Z7: 2 | AC7: 1 | AD7: =IF($E7="","",IFERROR(AVERAGE($T7,IF($L7="Y",$U7,1),$V7),"")) -> 0.33333333 | AE7: =IF($E7="","",IFERROR(IF($Q7>=$M7,1,0),0)) -> 0 | AF7: 1 | AG7: =IF($E7="","",IF($I7="Y",IFERROR($P7,0),1)) -> 1 | AH7: =IF($E7="","",IFERROR((Weights!$B$2*$O7 + Weights!$B$3*$AE7 + Weights!$B$4*$AD7 + Weights!$B$5*(1-$AC7) + Weights!$B$6*$AF7 + Weights!$B$7*$AG7)/SUM(Weights!$B$2:$B$7),"" )) -> 0.5 | AI7: =IF($E7="","",IF($O7=0,0,IFERROR($AH7/MAX(Weights!$B$8,$Y7)/MAX(Weights!$B$9,IF($Z7="",0,$Z7)), ""))) -> 0.19762846 | AJ7: (content + date + pagination expectations miss)
A8: 181601032026 | B8: 46025 | C8: Serper | D8: Pagination | E8: U009 | F8: =IF($E8="","",VLOOKUP($E8,Benchmark_URLs!$A$2:$L$46,4,FALSE)) -> https://www.federalreserve.gov/newsevents/pressreleases/2025-press.htm | H8: =IF($E8="","",VLOOKUP($E8,Benchmark_URLs!$A$2:$L$46,6,FALSE)) -> html | I8: =IF($E8="","",VLOOKUP($E8,Benchmark_URLs!$A$2:$L$46,7,FALSE)) -> N | J8: =IF($E8="","",VLOOKUP($E8,Benchmark_URLs!$A$2:$L$46,8,FALSE)) -> N | K8: =IF($E8="","",VLOOKUP($E8,Benchmark_URLs!$A$2:$L$46,9,FALSE)) -> Y | L8: =IF($E8="","",VLOOKUP($E8,Benchmark_URLs!$A$2:$L$46,10,FALSE)) -> Y | M8: =IF($E8="","",VLOOKUP($E8,Benchmark_URLs!$A$2:$L$46,11,FALSE)) -> 2000 | N8: 200 | O8: 1 | P8: 0 | Q8: 303 | R8: 303 | S8: 0 | T8: 1 | U8: 0 | V8: 0 | W8: 0 | Y8: 0.569 | Z8: 2 | AC8: 1 | AD8: =IF($E8="","",IFERROR(AVERAGE($T8,IF($L8="Y",$U8,1),$V8),"")) -> 0.33333333 | AE8: =IF($E8="","",IFERROR(IF($Q8>=$M8,1,0),0)) -> 0 | AF8: =IF($E8="","",IF($H8="pdf",IFERROR(IF($X8>=Weights!$B$10,1,0),0),1)) -> 1 | AG8: =IF($E8="","",IF($I8="Y",IFERROR($P8,0),1)) -> 1 | AH8: =IF($E8="","",IFERROR((Weights!$B$2*$O8 + Weights!$B$3*$AE8 + Weights!$B$4*$AD8 + Weights!$B$5*(1-$AC8) + Weights!$B$6*$AF8 + Weights!$B$7*$AG8)/SUM(Weights!$B$2:$B$7),"" )) -> 0.5 | AI8: =IF($E8="","",IF($O8=0,0,IFERROR($AH8/MAX(Weights!$B$8,$Y8)/MAX(Weights!$B$9,IF($Z8="",0,$Z8)), ""))) -> 0.43936731
A9: 182101032026 | B9: 46025 | C9: Serper | D9: JS_Heavy | E9: U016 | F9: =IF($E9="","",VLOOKUP($E9,Benchmark_URLs!$A$2:$L$46,4,FALSE)) -> https://react.dev/learn | H9: =IF($E9="","",VLOOKUP($E9,Benchmark_URLs!$A$2:$L$46,6,FALSE)) -> html | I9: =IF($E9="","",VLOOKUP($E9,Benchmark_URLs!$A$2:$L$46,7,FALSE)) -> Y | J9: =IF($E9="","",VLOOKUP($E9,Benchmark_URLs!$A$2:$L$46,8,FALSE)) -> N | K9: =IF($E9="","",VLOOKUP($E9,Benchmark_URLs!$A$2:$L$46,9,FALSE)) -> N | L9: =IF($E9="","",VLOOKUP($E9,Benchmark_URLs!$A$2:$L$46,10,FALSE)) -> Y | M9: =IF($E9="","",VLOOKUP($E9,Benchmark_URLs!$A$2:$L$46,11,FALSE)) -> 3000 | N9: 200 | O9: 1 | P9: 0 | Q9: 9800 | R9: 9800 | S9: 0 | T9: 1 | U9: 0 | V9: 0 | W9: 0 | Y9: 2.543 | Z9: 2 | AC9: 1 | AD9: =IF($E9="","",IFERROR(AVERAGE($T9,IF($L9="Y",$U9,1),$V9),"")) -> 0.33333333 | AE9: =IF($E9="","",IFERROR(IF($Q9>=$M9,1,0),0)) -> 1 | AF9: =IF($E9="","",IF($H9="pdf",IFERROR(IF($X9>=Weights!$B$10,1,0),0),1)) -> 1 | AG9: =IF($E9="","",IF($I9="Y",IFERROR($P9,0),1)) -> 0 | AH9: =IF($E9="","",IFERROR((Weights!$B$2*$O9 + Weights!$B$3*$AE9 + Weights!$B$4*$AD9 + Weights!$B$5*(1-$AC9) + Weights!$B$6*$AF9 + Weights!$B$7*$AG9)/SUM(Weights!$B$2:$B$7),"" )) -> 0.7 | AI9: =IF($E9="","",IF($O9=0,0,IFERROR($AH9/MAX(Weights!$B$8,$Y9)/MAX(Weights!$B$9,IF($Z9="",0,$Z9)), ""))) -> 0.13763272
A10: 182601032026 | B10: 46025 | C10: Serper | D10: JS_Heavy | E10: U017 | F10: =IF($E10="","",VLOOKUP($E10,Benchmark_URLs!$A$2:$L$46,4,FALSE)) -> https://nextjs.org/docs | H10: =IF($E10="","",VLOOKUP($E10,Benchmark_URLs!$A$2:$L$46,6,FALSE)) -> html | I10: =IF($E10="","",VLOOKUP($E10,Benchmark_URLs!$A$2:$L$46,7,FALSE)) -> Y | J10: =IF($E10="","",VLOOKUP($E10,Benchmark_URLs!$A$2:$L$46,8,FALSE)) -> N | K10: =IF($E10="","",VLOOKUP($E10,Benchmark_URLs!$A$2:$L$46,9,FALSE)) -> N | L10: =IF($E10="","",VLOOKUP($E10,Benchmark_URLs!$A$2:$L$46,10,FALSE)) -> Y | M10: =IF($E10="","",VLOOKUP($E10,Benchmark_URLs!$A$2:$L$46,11,FALSE)) -> 3000 | N10: 404 | O10: 0 | P10: 0 | S10: 0 | T10: 0 | U10: 0 | V10: 0 | W10: 0 | Y10: 0 | AC10: 0 | AD10: =IF($E10="","",IFERROR(AVERAGE($T10,IF($L10="Y",$U10,1),$V10),"")) -> 0 | AE10: =IF($E10="","",IFERROR(IF($Q10>=$M10,1,0),0)) -> 0 | AF10: =IF($E10="","",IF($H10="pdf",IFERROR(IF($X10>=Weights!$B$10,1,0),0),1)) -> 1 | AG10: =IF($E10="","",IF($I10="Y",IFERROR($P10,0),1)) -> 0 | AH10: =IF($E10="","",IFERROR((Weights!$B$2*$O10 + Weights!$B$3*$AE10 + Weights!$B$4*$AD10 + Weights!$B$5*(1-$AC10) + Weights!$B$6*$AF10 + Weights!$B$7*$AG10)/SUM(Weights!$B$2:$B$7),"" )) -> 0.25 | AI10: =IF($E10="","",IF($O10=0,0,IFERROR($AH10/MAX(Weights!$B$8,$Y10)/MAX(Weights!$B$9,IF($Z10="",0,$Z10)), ""))) -> 0
A11: 184501032026 | B11: 46025 | C11: Serper | D11: JS_Heavy | E11: U018 | F11: =IF($E11="","",VLOOKUP($E11,Benchmark_URLs!$A$2:$L$46,4,FALSE)) -> https://learn.microsoft.com/en-us/azure/architecture/ | H11: =IF($E11="","",VLOOKUP($E11,Benchmark_URLs!$A$2:$L$46,6,FALSE)) -> html | I11: =IF($E11="","",VLOOKUP($E11,Benchmark_URLs!$A$2:$L$46,7,FALSE)) -> Y | J11: =IF($E11="","",VLOOKUP($E11,Benchmark_URLs!$A$2:$L$46,8,FALSE)) -> N | K11: =IF($E11="","",VLOOKUP($E11,Benchmark_URLs!$A$2:$L$46,9,FALSE)) -> N | L11: =IF($E11="","",VLOOKUP($E11,Benchmark_URLs!$A$2:$L$46,10,FALSE)) -> Y | M11: =IF($E11="","",VLOOKUP($E11,Benchmark_URLs!$A$2:$L$46,11,FALSE)) -> 3000 | N11: 200 | O11: 1 | P11: 0 | Q11: 1100 | R11: 1100 | S11: 0 | T11: 1 | U11: 0 | V11: 1 | W11: 0 | Y11: 0.782 | Z11: 2 | AC11: 1 | AD11: =IF($E11="","",IFERROR(AVERAGE($T11,IF($L11="Y",$U11,1),$V11),"")) -> 0.66666667 | AE11: =IF($E11="","",IFERROR(IF($Q11>=$M11,1,0),0)) -> 0 | AG11: =IF($E11="","",IF($I11="Y",IFERROR($P11,0),1)) -> 0 | AH11: =IF($E11="","",IFERROR((Weights!$B$2*$O11 + Weights!$B$3*$AE11 + Weights!$B$4*$AD11 + Weights!$B$5*(1-$AC11) + Weights!$B$6*$AF11 + Weights!$B$7*$AG11)/SUM(Weights!$B$2:$B$7),"" )) -> 0.4 | AI11: =IF($E11="","",IF($O11=0,0,IFERROR($AH11/MAX(Weights!$B$8,$Y11)/MAX(Weights!$B$9,IF($Z11="",0,$Z11)), ""))) -> 0.25575448 | AJ11: In the case of React docs, the content extracted was long, but on the Microsoft Learn hub, it is coming out short—the tool is likely only picking up the 'main content,' or it's missing JavaScript rendering/section expansion.
A12: 185101032026 | B12: 46025 | C12: Serper | D12: PDF | E12: U024 | F12: =IF($E12="","",VLOOKUP($E12,Benchmark_URLs!$A$2:$L$46,4,FALSE)) -> https://www.federalreserve.gov/supervisionreg/srletters/sr1107.pdf | H12: =IF($E12="","",VLOOKUP($E12,Benchmark_URLs!$A$2:$L$46,6,FALSE)) -> pdf | I12: =IF($E12="","",VLOOKUP($E12,Benchmark_URLs!$A$2:$L$46,7,FALSE)) -> N | J12: =IF($E12="","",VLOOKUP($E12,Benchmark_URLs!$A$2:$L$46,8,FALSE)) -> N | K12: =IF($E12="","",VLOOKUP($E12,Benchmark_URLs!$A$2:$L$46,9,FALSE)) -> N | L12: =IF($E12="","",VLOOKUP($E12,Benchmark_URLs!$A$2:$L$46,10,FALSE)) -> Y | M12: =IF($E12="","",VLOOKUP($E12,Benchmark_URLs!$A$2:$L$46,11,FALSE)) -> 8000 | N12: 200 | O12: 1 | P12: 0 | Q12: 15337 | R12: 15337 | S12: 0 | T12: 1 | U12: 1 | V12: 1 | W12: 0 | X12: 5 | Y12: 0.845 | Z12: 2 | AC12: 1 | AD12: =IF($E12="","",IFERROR(AVERAGE($T12,IF($L12="Y",$U12,1),$V12),"")) -> 1 | AE12: =IF($E12="","",IFERROR(IF($Q12>=$M12,1,0),0)) -> 1 | AF12: =IF($E12="","",IF($H12="pdf",IFERROR(IF($X12>=Weights!$B$10,1,0),0),1)) -> 1 | AG12: =IF($E12="","",IF($I12="Y",IFERROR($P12,0),1)) -> 1 | AH12: =IF($E12="","",IFERROR((Weights!$B$2*$O12 + Weights!$B$3*$AE12 + Weights!$B$4*$AD12 + Weights!$B$5*(1-$AC12) + Weights!$B$6*$AF12 + Weights!$B$7*$AG12)/SUM(Weights!$B$2:$B$7),"" )) -> 0.85 | AI12: =IF($E12="","",IF($O12=0,0,IFERROR($AH12/MAX(Weights!$B$8,$Y12)/MAX(Weights!$B$9,IF($Z12="",0,$Z12)), ""))) -> 0.50295858
A13: 185501032026 | B13: 46025 | C13: Serper | D13: PDF | E13: U025 | F13: =IF($E13="","",VLOOKUP($E13,Benchmark_URLs!$A$2:$L$46,4,FALSE)) -> https://www.fdic.gov/resources/supervision-and-examinations/examination-policies-manual/risk-management-manual-complete.pdf | H13: =IF($E13="","",VLOOKUP($E13,Benchmark_URLs!$A$2:$L$46,6,FALSE)) -> pdf | I13: =IF($E13="","",VLOOKUP($E13,Benchmark_URLs!$A$2:$L$46,7,FALSE)) -> N | J13: =IF($E13="","",VLOOKUP($E13,Benchmark_URLs!$A$2:$L$46,8,FALSE)) -> N | K13: =IF($E13="","",VLOOKUP($E13,Benchmark_URLs!$A$2:$L$46,9,FALSE)) -> N | L13: =IF($E13="","",VLOOKUP($E13,Benchmark_URLs!$A$2:$L$46,10,FALSE)) -> Y | M13: =IF($E13="","",VLOOKUP($E13,Benchmark_URLs!$A$2:$L$46,11,FALSE)) -> 15000 | N13: 200 | O13: 1 | P13: 0 | Q13: 4484225 | R13: 4484225 | S13: 0 | T13: 1 | U13: 1 | V13: 0 | W13: 16 | X13: 848 | Y13: 13.419 | Z13: 2 | AB13: PDF parse OK; content way above min chars; date signals present; links present | AC13: 0 | AD13: =IF($E13="","",IFERROR(AVERAGE($T13,IF($L13="Y",$U13,1),$V13),"")) -> 0.66666667 | AE13: =IF($E13="","",IFERROR(IF($Q13>=$M13,1,0),0)) -> 1 | AF13: =IF($E13="","",IF($H13="pdf",IFERROR(IF($X13>=Weights!$B$10,1,0),0),1)) -> 1 | AG13: =IF($E13="","",IF($I13="Y",IFERROR($P13,0),1)) -> 1 | AH13: =IF($E13="","",IFERROR((Weights!$B$2*$O13 + Weights!$B$3*$AE13 + Weights!$B$4*$AD13 + Weights!$B$5*(1-$AC13) + Weights!$B$6*$AF13 + Weights!$B$7*$AG13)/SUM(Weights!$B$2:$B$7),"" )) -> 0.95 | AI13: =IF($E13="","",IF($O13=0,0,IFERROR($AH13/MAX(Weights!$B$8,$Y13)/MAX(Weights!$B$9,IF($Z13="",0,$Z13)), ""))) -> 0.035397571
A14: 190001032026 | B14: 46025 | C14: Serper | D14: Redirect | E14: U033 | F14: =IF($E14="","",VLOOKUP($E14,Benchmark_URLs!$A$2:$L$46,4,FALSE)) -> http://www.sec.gov | H14: =IF($E14="","",VLOOKUP($E14,Benchmark_URLs!$A$2:$L$46,6,FALSE)) -> html | I14: =IF($E14="","",VLOOKUP($E14,Benchmark_URLs!$A$2:$L$46,7,FALSE)) -> N | J14: =IF($E14="","",VLOOKUP($E14,Benchmark_URLs!$A$2:$L$46,8,FALSE)) -> N | K14: =IF($E14="","",VLOOKUP($E14,Benchmark_URLs!$A$2:$L$46,9,FALSE)) -> N | L14: =IF($E14="","",VLOOKUP($E14,Benchmark_URLs!$A$2:$L$46,10,FALSE)) -> Y | M14: =IF($E14="","",VLOOKUP($E14,Benchmark_URLs!$A$2:$L$46,11,FALSE)) -> 500 | N14: 200 | O14: 1 | P14: 0 | Q14: 320 | R14: 320 | S14: 0 | T14: 1 | U14: 0 | V14: 0 | W14: 0 | Y14: 0.595 | Z14: 2 | AC14: 0 | AD14: =IF($E14="","",IFERROR(AVERAGE($T14,IF($L14="Y",$U14,1),$V14),"")) -> 0.33333333 | AE14: =IF($E14="","",IFERROR(IF($Q14>=$M14,1,0),0)) -> 0 | AG14: =IF($E14="","",IF($I14="Y",IFERROR($P14,0),1)) -> 1 | AH14: =IF($E14="","",IFERROR((Weights!$B$2*$O14 + Weights!$B$3*$AE14 + Weights!$B$4*$AD14 + Weights!$B$5*(1-$AC14) + Weights!$B$6*$AF14 + Weights!$B$7*$AG14)/SUM(Weights!$B$2:$B$7),"" )) -> 0.55 | AI14: =IF($E14="","",IF($O14=0,0,IFERROR($AH14/MAX(Weights!$B$8,$Y14)/MAX(Weights!$B$9,IF($Z14="",0,$Z14)), ""))) -> 0.46218487
A15: 190301032026 | B15: 46025 | C15: Serper | D15: Redirect | E15: U034 | F15: =IF($E15="","",VLOOKUP($E15,Benchmark_URLs!$A$2:$L$46,4,FALSE)) -> http://www.fdic.gov | H15: =IF($E15="","",VLOOKUP($E15,Benchmark_URLs!$A$2:$L$46,6,FALSE)) -> html | I15: =IF($E15="","",VLOOKUP($E15,Benchmark_URLs!$A$2:$L$46,7,FALSE)) -> N | J15: =IF($E15="","",VLOOKUP($E15,Benchmark_URLs!$A$2:$L$46,8,FALSE)) -> N | K15: =IF($E15="","",VLOOKUP($E15,Benchmark_URLs!$A$2:$L$46,9,FALSE)) -> N | L15: =IF($E15="","",VLOOKUP($E15,Benchmark_URLs!$A$2:$L$46,10,FALSE)) -> Y | M15: =IF($E15="","",VLOOKUP($E15,Benchmark_URLs!$A$2:$L$46,11,FALSE)) -> 500 | N15: 200 | O15: 1 | P15: 0 | Q15: 3614 | R15: 3614 | S15: 0 | T15: 1 | U15: 1 | V15: 0 | W15: 0 | Y15: 1.089 | Z15: 2 | AB15: Redirect HTTP→HTTPS OK; content length OK; dates present | AC15: 0 | AD15: =IF($E15="","",IFERROR(AVERAGE($T15,IF($L15="Y",$U15,1),$V15),"")) -> 0.66666667 | AE15: =IF($E15="","",IFERROR(IF($Q15>=$M15,1,0),0)) -> 1 | AG15: =IF($E15="","",IF($I15="Y",IFERROR($P15,0),1)) -> 1 | AH15: =IF($E15="","",IFERROR((Weights!$B$2*$O15 + Weights!$B$3*$AE15 + Weights!$B$4*$AD15 + Weights!$B$5*(1-$AC15) + Weights!$B$6*$AF15 + Weights!$B$7*$AG15)/SUM(Weights!$B$2:$B$7),"" )) -> 0.85 | AI15: =IF($E15="","",IF($O15=0,0,IFERROR($AH15/MAX(Weights!$B$8,$Y15)/MAX(Weights!$B$9,IF($Z15="",0,$Z15)), ""))) -> 0.3902663
A16: 190701032026 | B16: 46025 | C16: Serper | D16: Hard | E16: U036 | F16: =IF($E16="","",VLOOKUP($E16,Benchmark_URLs!$A$2:$L$46,4,FALSE)) -> https://www.bcg.com/capabilities/digital-technology-data/insights | H16: =IF($E16="","",VLOOKUP($E16,Benchmark_URLs!$A$2:$L$46,6,FALSE)) -> html | I16: =IF($E16="","",VLOOKUP($E16,Benchmark_URLs!$A$2:$L$46,7,FALSE)) -> Y | J16: =IF($E16="","",VLOOKUP($E16,Benchmark_URLs!$A$2:$L$46,8,FALSE)) -> N | K16: =IF($E16="","",VLOOKUP($E16,Benchmark_URLs!$A$2:$L$46,9,FALSE)) -> Y | L16: =IF($E16="","",VLOOKUP($E16,Benchmark_URLs!$A$2:$L$46,10,FALSE)) -> Y | M16: =IF($E16="","",VLOOKUP($E16,Benchmark_URLs!$A$2:$L$46,11,FALSE)) -> 2500 | N16: 200 | O16: 1 | P16: 0 | Q16: 380 | R16: 380 | S16: 0 | T16: 1 | U16: 0 | V16: 0 | W16: 0 | Y16: 1.892 | Z16: 2 | AB16: JS + pagination expected (insights listing), but extraction sirf top intro tak limited; content length + date missing | AC16: 0 | AD16: =IF($E16="","",IFERROR(AVERAGE($T16,IF($L16="Y",$U16,1),$V16),"")) -> 0.33333333 | AE16: =IF($E16="","",IFERROR(IF($Q16>=$M16,1,0),0)) -> 0 | AG16: =IF($E16="","",IF($I16="Y",IFERROR($P16,0),1)) -> 0 | AH16: =IF($E16="","",IFERROR((Weights!$B$2*$O16 + Weights!$B$3*$AE16 + Weights!$B$4*$AD16 + Weights!$B$5*(1-$AC16) + Weights!$B$6*$AF16 + Weights!$B$7*$AG16)/SUM(Weights!$B$2:$B$7),"" )) -> 0.5 | AI16: =IF($E16="","",IF($O16=0,0,IFERROR($AH16/MAX(Weights!$B$8,$Y16)/MAX(Weights!$B$9,IF($Z16="",0,$Z16)), ""))) -> 0.13213531 | AJ16: Expected JS + pagination + date, but output sirf short static intro (listing load nahi hua), isliye content_ok=0 + js_ok=0 + date_present=0.
A17: 190901032026 | B17: 46025 | C17: Serper | D17: Hard | E17: U037 | F17: =IF($E17="","",VLOOKUP($E17,Benchmark_URLs!$A$2:$L$46,4,FALSE)) -> https://www.mckinsey.com/featured-insights/mckinsey-explainers/what-is-digital-transformation | H17: =IF($E17="","",VLOOKUP($E17,Benchmark_URLs!$A$2:$L$46,6,FALSE)) -> html | I17: =IF($E17="","",VLOOKUP($E17,Benchmark_URLs!$A$2:$L$46,7,FALSE)) -> Y | J17: =IF($E17="","",VLOOKUP($E17,Benchmark_URLs!$A$2:$L$46,8,FALSE)) -> N | K17: =IF($E17="","",VLOOKUP($E17,Benchmark_URLs!$A$2:$L$46,9,FALSE)) -> N | L17: =IF($E17="","",VLOOKUP($E17,Benchmark_URLs!$A$2:$L$46,10,FALSE)) -> Y | M17: =IF($E17="","",VLOOKUP($E17,Benchmark_URLs!$A$2:$L$46,11,FALSE)) -> 2500 | N17: 200 | O17: 1 | P17: 0 | Q17: 16012 | R17: 16012 | S17: 0 | T17: 1 | U17: 1 | V17: 0 | W17: 0 | Y17: 1.037 | Z17: 2 | AB17: Content + date OK; expected_js_required=Y but js_rendered flag missing/0 → js_ok fail | AC17: 0 | AD17: =IF($E17="","",IFERROR(AVERAGE($T17,IF($L17="Y",$U17,1),$V17),"")) -> 0.66666667 | AE17: =IF($E17="","",IFERROR(IF($Q17>=$M17,1,0),0)) -> 1 | AG17: =IF($E17="","",IF($I17="Y",IFERROR($P17,0),1)) -> 0 | AH17: =IF($E17="","",IFERROR((Weights!$B$2*$O17 + Weights!$B$3*$AE17 + Weights!$B$4*$AD17 + Weights!$B$5*(1-$AC17) + Weights!$B$6*$AF17 + Weights!$B$7*$AG17)/SUM(Weights!$B$2:$B$7),"" )) -> 0.8 | AI17: =IF($E17="","",IF($O17=0,0,IFERROR($AH17/MAX(Weights!$B$8,$Y17)/MAX(Weights!$B$9,IF($Z17="",0,$Z17)), ""))) -> 0.38572806
A18: 191801032026 | B18: 46025 | C18: Serper | D18: JSON_API | E18: U043 | F18: =IF($E18="","",VLOOKUP($E18,Benchmark_URLs!$A$2:$L$46,4,FALSE)) -> https://search.worldbank.org/api/v2/news?format=json&rows=20&fct=displayconttype_exact,topic_exact,lang_exact,count_exact,countcode_exact,admreg_exact&src=cq55&apilang=en&lang_exact=English&displayconttype_exact=Press%20Release&os=0 | H18: =IF($E18="","",VLOOKUP($E18,Benchmark_URLs!$A$2:$L$46,6,FALSE)) -> json | I18: =IF($E18="","",VLOOKUP($E18,Benchmark_URLs!$A$2:$L$46,7,FALSE)) -> N | J18: =IF($E18="","",VLOOKUP($E18,Benchmark_URLs!$A$2:$L$46,8,FALSE)) -> N | K18: =IF($E18="","",VLOOKUP($E18,Benchmark_URLs!$A$2:$L$46,9,FALSE)) -> Y | L18: =IF($E18="","",VLOOKUP($E18,Benchmark_URLs!$A$2:$L$46,10,FALSE)) -> Y | M18: =IF($E18="","",VLOOKUP($E18,Benchmark_URLs!$A$2:$L$46,11,FALSE)) -> 1000 | N18: 404 | O18: 0 | P18: 0 | Q18: 0 | R18: 0 | S18: 0 | T18: 0 | U18: 0 | V18: 0 | W18: 0 | Y18: 0 | Z18: 0 | AC18: =IF($E18="","",IF($R18>0,MIN(1,$S18/$R18),"")) | AD18: =IF($E18="","",IFERROR(AVERAGE($T18,IF($L18="Y",$U18,1),$V18),"")) -> 0 | AE18: =IF($E18="","",IFERROR(IF($Q18>=$M18,1,0),0)) -> 0 | AG18: 0 | AH18: =IF($E18="","",IFERROR((Weights!$B$2*$O18 + Weights!$B$3*$AE18 + Weights!$B$4*$AD18 + Weights!$B$5*(1-$AC18) + Weights!$B$6*$AF18 + Weights!$B$7*$AG18)/SUM(Weights!$B$2:$B$7),"" )) -> 0.15 | AI18: =IF($E18="","",IF($O18=0,0,IFERROR($AH18/MAX(Weights!$B$8,$Y18)/MAX(Weights!$B$9,IF($Z18="",0,$Z18)), ""))) -> 0
A19: 191901032026 | B19: 46025 | C19: Serper | D19: JSON_API | E19: U044 | F19: =IF($E19="","",VLOOKUP($E19,Benchmark_URLs!$A$2:$L$46,4,FALSE)) -> https://search.worldbank.org/api/v2/news?format=json&rows=20&fct=displayconttype_exact,topic_exact,lang_exact,count_exact,countcode_exact,admreg_exact&src=cq55&apilang=en&lang_exact=English&displayconttype_exact=Press%20Release&os=20 | H19: =IF($E19="","",VLOOKUP($E19,Benchmark_URLs!$A$2:$L$46,6,FALSE)) -> json | I19: =IF($E19="","",VLOOKUP($E19,Benchmark_URLs!$A$2:$L$46,7,FALSE)) -> N | J19: =IF($E19="","",VLOOKUP($E19,Benchmark_URLs!$A$2:$L$46,8,FALSE)) -> N | K19: =IF($E19="","",VLOOKUP($E19,Benchmark_URLs!$A$2:$L$46,9,FALSE)) -> Y | L19: =IF($E19="","",VLOOKUP($E19,Benchmark_URLs!$A$2:$L$46,10,FALSE)) -> Y | M19: =IF($E19="","",VLOOKUP($E19,Benchmark_URLs!$A$2:$L$46,11,FALSE)) -> 1000 | N19: 404 | O19: 0 | P19: 0 | Q19: 0 | R19: 0 | S19: 0 | T19: 0 | U19: 0 | V19: 0 | W19: 0 | Y19: 0 | Z19: 0 | AC19: =IF($E19="","",IF($R19>0,MIN(1,$S19/$R19),"")) | AD19: =IF($E19="","",IFERROR(AVERAGE($T19,IF($L19="Y",$U19,1),$V19),"")) -> 0 | AE19: =IF($E19="","",IFERROR(IF($Q19>=$M19,1,0),0)) -> 0 | AG19: 0 | AH19: =IF($E19="","",IFERROR((Weights!$B$2*$O19 + Weights!$B$3*$AE19 + Weights!$B$4*$AD19 + Weights!$B$5*(1-$AC19) + Weights!$B$6*$AF19 + Weights!$B$7*$AG19)/SUM(Weights!$B$2:$B$7),"" )) -> 0.15 | AI19: =IF($E19="","",IF($O19=0,0,IFERROR($AH19/MAX(Weights!$B$8,$Y19)/MAX(Weights!$B$9,IF($Z19="",0,$Z19)), ""))) -> 0
A20: 195501032026 | B20: 46025 | C20: Tavily | D20: Static_HTML | E20: U001 | F20: =IF($E20="","",VLOOKUP($E20,Benchmark_URLs!$A$2:$L$46,4,FALSE)) -> https://www.federalreserve.gov/supervisionreg.htm | H20: =IF($E20="","",VLOOKUP($E20,Benchmark_URLs!$A$2:$L$46,6,FALSE)) -> html | I20: =IF($E20="","",VLOOKUP($E20,Benchmark_URLs!$A$2:$L$46,7,FALSE)) -> N | J20: =IF($E20="","",VLOOKUP($E20,Benchmark_URLs!$A$2:$L$46,8,FALSE)) -> N | K20: =IF($E20="","",VLOOKUP($E20,Benchmark_URLs!$A$2:$L$46,9,FALSE)) -> N | L20: =IF($E20="","",VLOOKUP($E20,Benchmark_URLs!$A$2:$L$46,10,FALSE)) -> Y | M20: =IF($E20="","",VLOOKUP($E20,Benchmark_URLs!$A$2:$L$46,11,FALSE)) -> 4000 | N20: 200 | O20: 1 | P20: 0 | Q20: 6985 | R20: 8837 | S20: 1852 | T20: 1 | U20: 1 | V20: 0 | W20: 22 | Y20: 0.36 | Z20: 3 | AC20: =IF($E20="","",IF($R20>0,MIN(1,$S20/$R20),"")) -> 0.20957338 | AD20: =IF($E20="","",IFERROR(AVERAGE($T20,IF($L20="Y",$U20,1),$V20),"")) -> 0.66666667 | AE20: =IF($E20="","",IFERROR(IF($Q20>=$M20,1,0),0)) -> 1 | AG20: =IF($E20="","",IF($I20="Y",IFERROR($P20,0),1)) -> 1 | AH20: =IF($E20="","",IFERROR((Weights!$B$2*$O20 + Weights!$B$3*$AE20 + Weights!$B$4*$AD20 + Weights!$B$5*(1-$AC20) + Weights!$B$6*$AF20 + Weights!$B$7*$AG20)/SUM(Weights!$B$2:$B$7),"" )) -> 0.81856399 | AI20: =IF($E20="","",IF($O20=0,0,IFERROR($AH20/MAX(Weights!$B$8,$Y20)/MAX(Weights!$B$9,IF($Z20="",0,$Z20)), ""))) -> 0.75792962
A21: 140501042026 | B21: 46026 | C21: Tavily | D21: Static_HTML | E21: U002 | F21: =IF($E21="","",VLOOKUP($E21,Benchmark_URLs!$A$2:$L$46,4,FALSE)) -> https://www.occ.treas.gov/publications-and-resources/publications/comptrollers-handbook/index-comptrollers-handbook.html | H21: =IF($E21="","",VLOOKUP($E21,Benchmark_URLs!$A$2:$L$46,6,FALSE)) -> html | I21: =IF($E21="","",VLOOKUP($E21,Benchmark_URLs!$A$2:$L$46,7,FALSE)) -> N | J21: =IF($E21="","",VLOOKUP($E21,Benchmark_URLs!$A$2:$L$46,8,FALSE)) -> N | K21: =IF($E21="","",VLOOKUP($E21,Benchmark_URLs!$A$2:$L$46,9,FALSE)) -> N | L21: =IF($E21="","",VLOOKUP($E21,Benchmark_URLs!$A$2:$L$46,10,FALSE)) -> Y | M21: =IF($E21="","",VLOOKUP($E21,Benchmark_URLs!$A$2:$L$46,11,FALSE)) -> 3000 | N21: 200 | O21: 1 | P21: 0 | Q21: 30096 | R21: 49681 | S21: 19585 | T21: 1 | U21: 1 | V21: 0 | W21: 98 | Y21: 5.25 | Z21: 3 | AB21: Page content + dates captured; pagination controls also present | AC21: =IF($E21="","",IF($R21>0,MIN(1,$S21/$R21),"")) -> 0.39421509 | AD21: =IF($E21="","",IFERROR(AVERAGE($T21,IF($L21="Y",$U21,1),$V21),"")) -> 0.66666667 | AE21: =IF($E21="","",IFERROR(IF($Q21>=$M21,1,0),0)) -> 1 | AG21: =IF($E21="","",IF($I21="Y",IFERROR($P21,0),1)) -> 1 | AH21: =IF($E21="","",IFERROR((Weights!$B$2*$O21 + Weights!$B$3*$AE21 + Weights!$B$4*$AD21 + Weights!$B$5*(1-$AC21) + Weights!$B$6*$AF21 + Weights!$B$7*$AG21)/SUM(Weights!$B$2:$B$7),"" )) -> 0.79086774 | AI21: =IF($E21="","",IF($O21=0,0,IFERROR($AH21/MAX(Weights!$B$8,$Y21)/MAX(Weights!$B$9,IF($Z21="",0,$Z21)), ""))) -> 0.050213825
A22: 141401042026 | B22: 46026 | C22: Tavily | D22: Static_HTML | E22: U003 | F22: =IF($E22="","",VLOOKUP($E22,Benchmark_URLs!$A$2:$L$46,4,FALSE)) -> https://www.fdic.gov/bank-examinations/examination-manuals | H22: =IF($E22="","",VLOOKUP($E22,Benchmark_URLs!$A$2:$L$46,6,FALSE)) -> html | I22: =IF($E22="","",VLOOKUP($E22,Benchmark_URLs!$A$2:$L$46,7,FALSE)) -> N | J22: =IF($E22="","",VLOOKUP($E22,Benchmark_URLs!$A$2:$L$46,8,FALSE)) -> N | K22: =IF($E22="","",VLOOKUP($E22,Benchmark_URLs!$A$2:$L$46,9,FALSE)) -> N | L22: =IF($E22="","",VLOOKUP($E22,Benchmark_URLs!$A$2:$L$46,10,FALSE)) -> Y | M22: =IF($E22="","",VLOOKUP($E22,Benchmark_URLs!$A$2:$L$46,11,FALSE)) -> 2000 | N22: 200 | O22: 1 | P22: 0 | Q22: 8500 | R22: 15000 | S22: 6500 | T22: 1 | U22: 1 | V22: 0 | W22: 120 | Y22: 1.75 | Z22: 3 | AB22: Manual hub page; multiple handbook links + dates present | AC22: =IF($E22="","",IF($R22>0,MIN(1,$S22/$R22),"")) -> 0.43333333 | AD22: =IF($E22="","",IFERROR(AVERAGE($T22,IF($L22="Y",$U22,1),$V22),"")) -> 0.66666667 | AE22: =IF($E22="","",IFERROR(IF($Q22>=$M22,1,0),0)) -> 1 | AG22: =IF($E22="","",IF($I22="Y",IFERROR($P22,0),1)) -> 1 | AH22: =IF($E22="","",IFERROR((Weights!$B$2*$O22 + Weights!$B$3*$AE22 + Weights!$B$4*$AD22 + Weights!$B$5*(1-$AC22) + Weights!$B$6*$AF22 + Weights!$B$7*$AG22)/SUM(Weights!$B$2:$B$7),"" )) -> 0.785 | AI22: =IF($E22="","",IF($O22=0,0,IFERROR($AH22/MAX(Weights!$B$8,$Y22)/MAX(Weights!$B$9,IF($Z22="",0,$Z22)), ""))) -> 0.14952381
A23: 142001042026 | B23: 46026 | C23: Tavily | D23: Table_Heavy | E23: U004 | F23: =IF($E23="","",VLOOKUP($E23,Benchmark_URLs!$A$2:$L$46,4,FALSE)) -> https://www.sec.gov/data-research/sec-markets-data/form-n-port-data-sets | H23: =IF($E23="","",VLOOKUP($E23,Benchmark_URLs!$A$2:$L$46,6,FALSE)) -> html | I23: =IF($E23="","",VLOOKUP($E23,Benchmark_URLs!$A$2:$L$46,7,FALSE)) -> N | J23: =IF($E23="","",VLOOKUP($E23,Benchmark_URLs!$A$2:$L$46,8,FALSE)) -> Y | K23: =IF($E23="","",VLOOKUP($E23,Benchmark_URLs!$A$2:$L$46,9,FALSE)) -> N | L23: =IF($E23="","",VLOOKUP($E23,Benchmark_URLs!$A$2:$L$46,10,FALSE)) -> Y | M23: =IF($E23="","",VLOOKUP($E23,Benchmark_URLs!$A$2:$L$46,11,FALSE)) -> 2000 | N23: 200 | O23: 1 | P23: 0 | Q23: 0 | R23: 0 | S23: 0 | T23: 0 | U23: 0 | V23: 0 | W23: 0 | Y23: 0.56 | Z23: 3 | AC23: =IF($E23="","",IF($R23>0,MIN(1,$S23/$R23),"")) | AD23: =IF($E23="","",IFERROR(AVERAGE($T23,IF($L23="Y",$U23,1),$V23),"")) -> 0 | AE23: =IF($E23="","",IFERROR(IF($Q23>=$M23,1,0),0)) -> 0 | AH23: =IF($E23="","",IFERROR((Weights!$B$2*$O23 + Weights!$B$3*$AE23 + Weights!$B$4*$AD23 + Weights!$B$5*(1-$AC23) + Weights!$B$6*$AF23 + Weights!$B$7*$AG23)/SUM(Weights!$B$2:$B$7),"" )) -> 0.45 | AI23: =IF($E23="","",IF($O23=0,0,IFERROR($AH23/MAX(Weights!$B$8,$Y23)/MAX(Weights!$B$9,IF($Z23="",0,$Z23)), ""))) -> 0.26785714
A24: 142501042026 | B24: 46026 | C24: Tavily | D24: Table_Heavy | E24: U012 | F24: =IF($E24="","",VLOOKUP($E24,Benchmark_URLs!$A$2:$L$46,4,FALSE)) -> https://fred.stlouisfed.org/series/GDP | H24: =IF($E24="","",VLOOKUP($E24,Benchmark_URLs!$A$2:$L$46,6,FALSE)) -> html | I24: =IF($E24="","",VLOOKUP($E24,Benchmark_URLs!$A$2:$L$46,7,FALSE)) -> Y | J24: =IF($E24="","",VLOOKUP($E24,Benchmark_URLs!$A$2:$L$46,8,FALSE)) -> Y | K24: =IF($E24="","",VLOOKUP($E24,Benchmark_URLs!$A$2:$L$46,9,FALSE)) -> N | L24: =IF($E24="","",VLOOKUP($E24,Benchmark_URLs!$A$2:$L$46,10,FALSE)) -> Y | M24: =IF($E24="","",VLOOKUP($E24,Benchmark_URLs!$A$2:$L$46,11,FALSE)) -> 2500 | N24: 200 | O24: 1 | P24: 0 | Q24: 18000 | R24: 45000 | S24: 27000 | T24: 1 | U24: 1 | V24: 0 | W24: 150 | Y24: 3.97 | Z24: 3 | AB24: Interactive JS-driven tables + charts; GDP values & update date visible | AC24: =IF($E24="","",IF($R24>0,MIN(1,$S24/$R24),"")) -> 0.6 | AD24: =IF($E24="","",IFERROR(AVERAGE($T24,IF($L24="Y",$U24,1),$V24),"")) -> 0.66666667 | AE24: =IF($E24="","",IFERROR(IF($Q24>=$M24,1,0),0)) -> 1 | AG24: 1 | AH24: =IF($E24="","",IFERROR((Weights!$B$2*$O24 + Weights!$B$3*$AE24 + Weights!$B$4*$AD24 + Weights!$B$5*(1-$AC24) + Weights!$B$6*$AF24 + Weights!$B$7*$AG24)/SUM(Weights!$B$2:$B$7),"" )) -> 0.76 | AI24: =IF($E24="","",IF($O24=0,0,IFERROR($AH24/MAX(Weights!$B$8,$Y24)/MAX(Weights!$B$9,IF($Z24="",0,$Z24)), ""))) -> 0.063811923
A25: 144201042026 | B25: 46026 | C25: Tavily | D25: Pagination | E25: U008 | F25: =IF($E25="","",VLOOKUP($E25,Benchmark_URLs!$A$2:$L$46,4,FALSE)) -> https://www.federalreserve.gov/newsevents/pressreleases.htm | H25: =IF($E25="","",VLOOKUP($E25,Benchmark_URLs!$A$2:$L$46,6,FALSE)) -> html | I25: =IF($E25="","",VLOOKUP($E25,Benchmark_URLs!$A$2:$L$46,7,FALSE)) -> N | J25: =IF($E25="","",VLOOKUP($E25,Benchmark_URLs!$A$2:$L$46,8,FALSE)) -> N | K25: =IF($E25="","",VLOOKUP($E25,Benchmark_URLs!$A$2:$L$46,9,FALSE)) -> Y | L25: =IF($E25="","",VLOOKUP($E25,Benchmark_URLs!$A$2:$L$46,10,FALSE)) -> Y | M25: =IF($E25="","",VLOOKUP($E25,Benchmark_URLs!$A$2:$L$46,11,FALSE)) -> 2000 | N25: 200 | O25: 1 | P25: 0 | Q25: 9000 | R25: 18000 | S25: 9000 | T25: 1 | U25: 1 | V25: 0 | W25: 40 | Y25: 0.33 | Z25: 3 | AB25: Year-wise pagination links (2010–2025), archive navigation present | AC25: =IF($E25="","",IF($R25>0,MIN(1,$S25/$R25),"")) -> 0.5 | AD25: =IF($E25="","",IFERROR(AVERAGE($T25,IF($L25="Y",$U25,1),$V25),"")) -> 0.66666667 | AE25: =IF($E25="","",IFERROR(IF($Q25>=$M25,1,0),0)) -> 1 | AG25: =IF($E25="","",IF($I25="Y",IFERROR($P25,0),1)) -> 1 | AH25: =IF($E25="","",IFERROR((Weights!$B$2*$O25 + Weights!$B$3*$AE25 + Weights!$B$4*$AD25 + Weights!$B$5*(1-$AC25) + Weights!$B$6*$AF25 + Weights!$B$7*$AG25)/SUM(Weights!$B$2:$B$7),"" )) -> 0.775 | AI25: =IF($E25="","",IF($O25=0,0,IFERROR($AH25/MAX(Weights!$B$8,$Y25)/MAX(Weights!$B$9,IF($Z25="",0,$Z25)), ""))) -> 0.78282828
A26: 144701042026 | B26: 46026 | C26: Tavily | D26: Pagination | E26: U009 | F26: =IF($E26="","",VLOOKUP($E26,Benchmark_URLs!$A$2:$L$46,4,FALSE)) -> https://www.federalreserve.gov/newsevents/pressreleases/2025-press.htm | H26: =IF($E26="","",VLOOKUP($E26,Benchmark_URLs!$A$2:$L$46,6,FALSE)) -> html | I26: =IF($E26="","",VLOOKUP($E26,Benchmark_URLs!$A$2:$L$46,7,FALSE)) -> N | J26: =IF($E26="","",VLOOKUP($E26,Benchmark_URLs!$A$2:$L$46,8,FALSE)) -> N | K26: =IF($E26="","",VLOOKUP($E26,Benchmark_URLs!$A$2:$L$46,9,FALSE)) -> Y | L26: =IF($E26="","",VLOOKUP($E26,Benchmark_URLs!$A$2:$L$46,10,FALSE)) -> Y | M26: =IF($E26="","",VLOOKUP($E26,Benchmark_URLs!$A$2:$L$46,11,FALSE)) -> 2000 | N26: 200 | O26: 1 | P26: 0 | Q26: 12000 | R26: 40000 | S26: 28000 | T26: 1 | U26: 1 | V26: 0 | W26: 180 | Y26: 1.38 | Z26: 3 | AB26: Year-specific paginated listing (2025); each item dated; archive navigation present | AC26: =IF($E26="","",IF($R26>0,MIN(1,$S26/$R26),"")) -> 0.7 | AD26: =IF($E26="","",IFERROR(AVERAGE($T26,IF($L26="Y",$U26,1),$V26),"")) -> 0.66666667 | AE26: =IF($E26="","",IFERROR(IF($Q26>=$M26,1,0),0)) -> 1 | AG26: =IF($E26="","",IF($I26="Y",IFERROR($P26,0),1)) -> 1 | AH26: =IF($E26="","",IFERROR((Weights!$B$2*$O26 + Weights!$B$3*$AE26 + Weights!$B$4*$AD26 + Weights!$B$5*(1-$AC26) + Weights!$B$6*$AF26 + Weights!$B$7*$AG26)/SUM(Weights!$B$2:$B$7),"" )) -> 0.745 | AI26: =IF($E26="","",IF($O26=0,0,IFERROR($AH26/MAX(Weights!$B$8,$Y26)/MAX(Weights!$B$9,IF($Z26="",0,$Z26)), ""))) -> 0.17995169
A27: 145201042026 | B27: 46026 | C27: Tavily | D27: JS_Heavy | E27: U016 | F27: =IF($E27="","",VLOOKUP($E27,Benchmark_URLs!$A$2:$L$46,4,FALSE)) -> https://react.dev/learn | H27: =IF($E27="","",VLOOKUP($E27,Benchmark_URLs!$A$2:$L$46,6,FALSE)) -> html | I27: =IF($E27="","",VLOOKUP($E27,Benchmark_URLs!$A$2:$L$46,7,FALSE)) -> Y | J27: =IF($E27="","",VLOOKUP($E27,Benchmark_URLs!$A$2:$L$46,8,FALSE)) -> N | K27: =IF($E27="","",VLOOKUP($E27,Benchmark_URLs!$A$2:$L$46,9,FALSE)) -> N | L27: =IF($E27="","",VLOOKUP($E27,Benchmark_URLs!$A$2:$L$46,10,FALSE)) -> Y | M27: =IF($E27="","",VLOOKUP($E27,Benchmark_URLs!$A$2:$L$46,11,FALSE)) -> 3000 | N27: 200 | O27: 1 | P27: 1 | Q27: 120000 | R27: 180000 | S27: 60000 | T27: 1 | U27: 0 | V27: 0 | W27: 350 | Y27: 1.48 | Z27: 3 | AB27: SPA-style React docs; content requires JS hydration; deep internal linking | AC27: =IF($E27="","",IF($R27>0,MIN(1,$S27/$R27),"")) -> 0.33333333 | AD27: =IF($E27="","",IFERROR(AVERAGE($T27,IF($L27="Y",$U27,1),$V27),"")) -> 0.33333333 | AE27: =IF($E27="","",IFERROR(IF($Q27>=$M27,1,0),0)) -> 1 | AG27: =IF($E27="","",IF($I27="Y",IFERROR($P27,0),1)) -> 1 | AH27: =IF($E27="","",IFERROR((Weights!$B$2*$O27 + Weights!$B$3*$AE27 + Weights!$B$4*$AD27 + Weights!$B$5*(1-$AC27) + Weights!$B$6*$AF27 + Weights!$B$7*$AG27)/SUM(Weights!$B$2:$B$7),"" )) -> 0.75 | AI27: =IF($E27="","",IF($O27=0,0,IFERROR($AH27/MAX(Weights!$B$8,$Y27)/MAX(Weights!$B$9,IF($Z27="",0,$Z27)), ""))) -> 0.16891892
A28: 145901042026 | B28: 46026 | C28: Tavily | D28: JS_Heavy | E28: U017 | F28: =IF($E28="","",VLOOKUP($E28,Benchmark_URLs!$A$2:$L$46,4,FALSE)) -> https://nextjs.org/docs | H28: =IF($E28="","",VLOOKUP($E28,Benchmark_URLs!$A$2:$L$46,6,FALSE)) -> html | I28: =IF($E28="","",VLOOKUP($E28,Benchmark_URLs!$A$2:$L$46,7,FALSE)) -> Y | J28: =IF($E28="","",VLOOKUP($E28,Benchmark_URLs!$A$2:$L$46,8,FALSE)) -> N | K28: =IF($E28="","",VLOOKUP($E28,Benchmark_URLs!$A$2:$L$46,9,FALSE)) -> N | L28: =IF($E28="","",VLOOKUP($E28,Benchmark_URLs!$A$2:$L$46,10,FALSE)) -> Y | M28: =IF($E28="","",VLOOKUP($E28,Benchmark_URLs!$A$2:$L$46,11,FALSE)) -> 3000 | N28: 200 | O28: 1 | P28: 1 | Q28: 150000 | R28: 220000 | S28: 70000 | T28: 1 | U28: 0 | V28: 0 | W28: 500 | Y28: 0.44 | Z28: 3 | AB28: JS-hydrated SPA docs; very large nav tree + API references; content visible only after JS | AC28: =IF($E28="","",IF($R28>0,MIN(1,$S28/$R28),"")) -> 0.31818182 | AD28: =IF($E28="","",IFERROR(AVERAGE($T28,IF($L28="Y",$U28,1),$V28),"")) -> 0.33333333 | AE28: =IF($E28="","",IFERROR(IF($Q28>=$M28,1,0),0)) -> 1 | AG28: =IF($E28="","",IF($I28="Y",IFERROR($P28,0),1)) -> 1 | AH28: =IF($E28="","",IFERROR((Weights!$B$2*$O28 + Weights!$B$3*$AE28 + Weights!$B$4*$AD28 + Weights!$B$5*(1-$AC28) + Weights!$B$6*$AF28 + Weights!$B$7*$AG28)/SUM(Weights!$B$2:$B$7),"" )) -> 0.75227273 | AI28: =IF($E28="","",IF($O28=0,0,IFERROR($AH28/MAX(Weights!$B$8,$Y28)/MAX(Weights!$B$9,IF($Z28="",0,$Z28)), ""))) -> 0.56990358
A29: 150501042026 | B29: 46026 | C29: Tavily | D29: JS_Heavy | E29: U018 | F29: =IF($E29="","",VLOOKUP($E29,Benchmark_URLs!$A$2:$L$46,4,FALSE)) -> https://learn.microsoft.com/en-us/azure/architecture/ | H29: =IF($E29="","",VLOOKUP($E29,Benchmark_URLs!$A$2:$L$46,6,FALSE)) -> html | I29: =IF($E29="","",VLOOKUP($E29,Benchmark_URLs!$A$2:$L$46,7,FALSE)) -> Y | J29: =IF($E29="","",VLOOKUP($E29,Benchmark_URLs!$A$2:$L$46,8,FALSE)) -> N | K29: =IF($E29="","",VLOOKUP($E29,Benchmark_URLs!$A$2:$L$46,9,FALSE)) -> N | L29: =IF($E29="","",VLOOKUP($E29,Benchmark_URLs!$A$2:$L$46,10,FALSE)) -> Y | M29: =IF($E29="","",VLOOKUP($E29,Benchmark_URLs!$A$2:$L$46,11,FALSE)) -> 3000 | N29: 200 | O29: 1 | P29: 1 | Q29: 35000 | R29: 90000 | S29: 55000 | T29: 1 | U29: 0 | V29: 0 | W29: 250 | Y29: 0.31 | Z29: 3 | AB29: Large JS-hydrated docs hub; category listings + deep internal links; content readable after JS | AC29: =IF($E29="","",IF($R29>0,MIN(1,$S29/$R29),"")) -> 0.61111111 | AD29: =IF($E29="","",IFERROR(AVERAGE($T29,IF($L29="Y",$U29,1),$V29),"")) -> 0.33333333 | AE29: =IF($E29="","",IFERROR(IF($Q29>=$M29,1,0),0)) -> 1 | AG29: =IF($E29="","",IF($I29="Y",IFERROR($P29,0),1)) -> 1 | AH29: =IF($E29="","",IFERROR((Weights!$B$2*$O29 + Weights!$B$3*$AE29 + Weights!$B$4*$AD29 + Weights!$B$5*(1-$AC29) + Weights!$B$6*$AF29 + Weights!$B$7*$AG29)/SUM(Weights!$B$2:$B$7),"" )) -> 0.70833333 | AI29: =IF($E29="","",IF($O29=0,0,IFERROR($AH29/MAX(Weights!$B$8,$Y29)/MAX(Weights!$B$9,IF($Z29="",0,$Z29)), ""))) -> 0.76164875
A30: 151101042026 | B30: 46026 | C30: Tavily | D30: PDF | E30: U024 | F30: =IF($E30="","",VLOOKUP($E30,Benchmark_URLs!$A$2:$L$46,4,FALSE)) -> https://www.federalreserve.gov/supervisionreg/srletters/sr1107.pdf | H30: =IF($E30="","",VLOOKUP($E30,Benchmark_URLs!$A$2:$L$46,6,FALSE)) -> pdf | I30: =IF($E30="","",VLOOKUP($E30,Benchmark_URLs!$A$2:$L$46,7,FALSE)) -> N | J30: =IF($E30="","",VLOOKUP($E30,Benchmark_URLs!$A$2:$L$46,8,FALSE)) -> N | K30: =IF($E30="","",VLOOKUP($E30,Benchmark_URLs!$A$2:$L$46,9,FALSE)) -> N | L30: =IF($E30="","",VLOOKUP($E30,Benchmark_URLs!$A$2:$L$46,10,FALSE)) -> Y | M30: =IF($E30="","",VLOOKUP($E30,Benchmark_URLs!$A$2:$L$46,11,FALSE)) -> 8000 | N30: 200 | O30: 1 | P30: 0 | Q30: 0 | R30: 0 | S30: 0 | T30: 0 | U30: 0 | V30: 0 | W30: 0 | Y30: 0.7 | Z30: 3 | AC30: 0 | AD30: =IF($E30="","",IFERROR(AVERAGE($T30,IF($L30="Y",$U30,1),$V30),"")) -> 0 | AE30: =IF($E30="","",IFERROR(IF($Q30>=$M30,1,0),0)) -> 0 | AG30: 0 | AH30: =IF($E30="","",IFERROR((Weights!$B$2*$O30 + Weights!$B$3*$AE30 + Weights!$B$4*$AD30 + Weights!$B$5*(1-$AC30) + Weights!$B$6*$AF30 + Weights!$B$7*$AG30)/SUM(Weights!$B$2:$B$7),"" )) -> 0.45 | AI30: =IF($E30="","",IF($O30=0,0,IFERROR($AH30/MAX(Weights!$B$8,$Y30)/MAX(Weights!$B$9,IF($Z30="",0,$Z30)), ""))) -> 0.21428571
A31: 151301042026 | B31: 46026 | C31: Tavily | D31: PDF | E31: U025 | F31: =IF($E31="","",VLOOKUP($E31,Benchmark_URLs!$A$2:$L$46,4,FALSE)) -> https://www.fdic.gov/resources/supervision-and-examinations/examination-policies-manual/risk-management-manual-complete.pdf | H31: =IF($E31="","",VLOOKUP($E31,Benchmark_URLs!$A$2:$L$46,6,FALSE)) -> pdf | I31: =IF($E31="","",VLOOKUP($E31,Benchmark_URLs!$A$2:$L$46,7,FALSE)) -> N | J31: =IF($E31="","",VLOOKUP($E31,Benchmark_URLs!$A$2:$L$46,8,FALSE)) -> N | K31: =IF($E31="","",VLOOKUP($E31,Benchmark_URLs!$A$2:$L$46,9,FALSE)) -> N | L31: =IF($E31="","",VLOOKUP($E31,Benchmark_URLs!$A$2:$L$46,10,FALSE)) -> Y | M31: =IF($E31="","",VLOOKUP($E31,Benchmark_URLs!$A$2:$L$46,11,FALSE)) -> 15000 | N31: 200 | O31: 1 | P31: 0 | Q31: 0 | R31: 0 | S31: 0 | T31: 0 | U31: 0 | V31: 0 | W31: 0 | Y31: 1.89 | Z31: 3 | AC31: 0 | AD31: =IF($E31="","",IFERROR(AVERAGE($T31,IF($L31="Y",$U31,1),$V31),"")) -> 0 | AE31: =IF($E31="","",IFERROR(IF($Q31>=$M31,1,0),0)) -> 0 | AG31: 0 | AH31: =IF($E31="","",IFERROR((Weights!$B$2*$O31 + Weights!$B$3*$AE31 + Weights!$B$4*$AD31 + Weights!$B$5*(1-$AC31) + Weights!$B$6*$AF31 + Weights!$B$7*$AG31)/SUM(Weights!$B$2:$B$7),"" )) -> 0.45 | AI31: =IF($E31="","",IF($O31=0,0,IFERROR($AH31/MAX(Weights!$B$8,$Y31)/MAX(Weights!$B$9,IF($Z31="",0,$Z31)), ""))) -> 0.079365079
A32: 151601042026 | B32: 46026 | C32: Tavily | D32: Redirect | E32: U033 | F32: =IF($E32="","",VLOOKUP($E32,Benchmark_URLs!$A$2:$L$46,4,FALSE)) -> http://www.sec.gov | H32: =IF($E32="","",VLOOKUP($E32,Benchmark_URLs!$A$2:$L$46,6,FALSE)) -> html | I32: =IF($E32="","",VLOOKUP($E32,Benchmark_URLs!$A$2:$L$46,7,FALSE)) -> N | J32: =IF($E32="","",VLOOKUP($E32,Benchmark_URLs!$A$2:$L$46,8,FALSE)) -> N | K32: =IF($E32="","",VLOOKUP($E32,Benchmark_URLs!$A$2:$L$46,9,FALSE)) -> N | L32: =IF($E32="","",VLOOKUP($E32,Benchmark_URLs!$A$2:$L$46,10,FALSE)) -> Y | M32: =IF($E32="","",VLOOKUP($E32,Benchmark_URLs!$A$2:$L$46,11,FALSE)) -> 500 | N32: 200 | O32: 1 | P32: 0 | Q32: 6000 | R32: 35000 | S32: 29000 | T32: 1 | U32: 1 | V32: 0 | W32: 200 | Y32: 0.15 | Z32: 3 | AB32: HTTP → HTTPS redirect followed; SEC homepage content successfully fetched | AC32: =IF($E32="","",IF($R32>0,MIN(1,$S32/$R32),"")) -> 0.82857143 | AD32: =IF($E32="","",IFERROR(AVERAGE($T32,IF($L32="Y",$U32,1),$V32),"")) -> 0.66666667 | AE32: =IF($E32="","",IFERROR(IF($Q32>=$M32,1,0),0)) -> 1 | AG32: =IF($E32="","",IF($I32="Y",IFERROR($P32,0),1)) -> 1 | AH32: =IF($E32="","",IFERROR((Weights!$B$2*$O32 + Weights!$B$3*$AE32 + Weights!$B$4*$AD32 + Weights!$B$5*(1-$AC32) + Weights!$B$6*$AF32 + Weights!$B$7*$AG32)/SUM(Weights!$B$2:$B$7),"" )) -> 0.72571429 | AI32: =IF($E32="","",IF($O32=0,0,IFERROR($AH32/MAX(Weights!$B$8,$Y32)/MAX(Weights!$B$9,IF($Z32="",0,$Z32)), ""))) -> 0.96761905
A33: 152401042026 | B33: 46026 | C33: Tavily | D33: Redirect | E33: U034 | F33: =IF($E33="","",VLOOKUP($E33,Benchmark_URLs!$A$2:$L$46,4,FALSE)) -> http://www.fdic.gov | H33: =IF($E33="","",VLOOKUP($E33,Benchmark_URLs!$A$2:$L$46,6,FALSE)) -> html | I33: =IF($E33="","",VLOOKUP($E33,Benchmark_URLs!$A$2:$L$46,7,FALSE)) -> N | J33: =IF($E33="","",VLOOKUP($E33,Benchmark_URLs!$A$2:$L$46,8,FALSE)) -> N | K33: =IF($E33="","",VLOOKUP($E33,Benchmark_URLs!$A$2:$L$46,9,FALSE)) -> N | L33: =IF($E33="","",VLOOKUP($E33,Benchmark_URLs!$A$2:$L$46,10,FALSE)) -> Y | M33: =IF($E33="","",VLOOKUP($E33,Benchmark_URLs!$A$2:$L$46,11,FALSE)) -> 500 | N33: 200 | O33: 1 | P33: 0 | Q33: 7500 | R33: 55000 | S33: 47500 | T33: 1 | U33: 1 | V33: 0 | W33: 300 | Y33: 0.23 | Z33: 3 | AB33: HTTP → HTTPS redirect followed successfully; FDIC homepage content extracted | AC33: =IF($E33="","",IF($R33>0,MIN(1,$S33/$R33),"")) -> 0.86363636 | AD33: =IF($E33="","",IFERROR(AVERAGE($T33,IF($L33="Y",$U33,1),$V33),"")) -> 0.66666667 | AE33: =IF($E33="","",IFERROR(IF($Q33>=$M33,1,0),0)) -> 1 | AG33: =IF($E33="","",IF($I33="Y",IFERROR($P33,0),1)) -> 1 | AH33: =IF($E33="","",IFERROR((Weights!$B$2*$O33 + Weights!$B$3*$AE33 + Weights!$B$4*$AD33 + Weights!$B$5*(1-$AC33) + Weights!$B$6*$AF33 + Weights!$B$7*$AG33)/SUM(Weights!$B$2:$B$7),"" )) -> 0.72045455 | AI33: =IF($E33="","",IF($O33=0,0,IFERROR($AH33/MAX(Weights!$B$8,$Y33)/MAX(Weights!$B$9,IF($Z33="",0,$Z33)), ""))) -> 0.96060606
A34: 153501042026 | B34: 46026 | C34: Tavily | D34: Hard | E34: U036 | F34: =IF($E34="","",VLOOKUP($E34,Benchmark_URLs!$A$2:$L$46,4,FALSE)) -> https://www.bcg.com/capabilities/digital-technology-data/insights | H34: =IF($E34="","",VLOOKUP($E34,Benchmark_URLs!$A$2:$L$46,6,FALSE)) -> html | I34: =IF($E34="","",VLOOKUP($E34,Benchmark_URLs!$A$2:$L$46,7,FALSE)) -> Y | J34: =IF($E34="","",VLOOKUP($E34,Benchmark_URLs!$A$2:$L$46,8,FALSE)) -> N | K34: =IF($E34="","",VLOOKUP($E34,Benchmark_URLs!$A$2:$L$46,9,FALSE)) -> Y | L34: =IF($E34="","",VLOOKUP($E34,Benchmark_URLs!$A$2:$L$46,10,FALSE)) -> Y | M34: =IF($E34="","",VLOOKUP($E34,Benchmark_URLs!$A$2:$L$46,11,FALSE)) -> 2500 | N34: 200 | O34: 1 | P34: 0 | Q34: 0 | R34: 0 | S34: 0 | T34: 0 | U34: 0 | V34: 0 | W34: 0 | Y34: 11.31 | Z34: 3 | AB34: No Results Found | AC34: =IF($E34="","",IF($R34>0,MIN(1,$S34/$R34),"")) | AD34: =IF($E34="","",IFERROR(AVERAGE($T34,IF($L34="Y",$U34,1),$V34),"")) -> 0 | AE34: =IF($E34="","",IFERROR(IF($Q34>=$M34,1,0),0)) -> 0 | AG34: =IF($E34="","",IF($I34="Y",IFERROR($P34,0),1)) -> 0 | AH34: =IF($E34="","",IFERROR((Weights!$B$2*$O34 + Weights!$B$3*$AE34 + Weights!$B$4*$AD34 + Weights!$B$5*(1-$AC34) + Weights!$B$6*$AF34 + Weights!$B$7*$AG34)/SUM(Weights!$B$2:$B$7),"" )) -> 0.45 | AI34: =IF($E34="","",IF($O34=0,0,IFERROR($AH34/MAX(Weights!$B$8,$Y34)/MAX(Weights!$B$9,IF($Z34="",0,$Z34)), ""))) -> 0.013262599
A35: 154001042026 | B35: 46026 | C35: Tavily | D35: Hard | E35: U037 | F35: =IF($E35="","",VLOOKUP($E35,Benchmark_URLs!$A$2:$L$46,4,FALSE)) -> https://www.mckinsey.com/featured-insights/mckinsey-explainers/what-is-digital-transformation | H35: =IF($E35="","",VLOOKUP($E35,Benchmark_URLs!$A$2:$L$46,6,FALSE)) -> html | I35: =IF($E35="","",VLOOKUP($E35,Benchmark_URLs!$A$2:$L$46,7,FALSE)) -> Y | J35: =IF($E35="","",VLOOKUP($E35,Benchmark_URLs!$A$2:$L$46,8,FALSE)) -> N | K35: =IF($E35="","",VLOOKUP($E35,Benchmark_URLs!$A$2:$L$46,9,FALSE)) -> N | L35: =IF($E35="","",VLOOKUP($E35,Benchmark_URLs!$A$2:$L$46,10,FALSE)) -> Y | M35: =IF($E35="","",VLOOKUP($E35,Benchmark_URLs!$A$2:$L$46,11,FALSE)) -> 2500 | N35: 200 | O35: 1 | P35: 0 | Q35: 0 | R35: 0 | S35: 0 | T35: 0 | U35: 0 | V35: 0 | W35: 0 | Y35: 15.39 | Z35: 3 | AB35: No Results Found | AC35: =IF($E35="","",IF($R35>0,MIN(1,$S35/$R35),"")) | AD35: =IF($E35="","",IFERROR(AVERAGE($T35,IF($L35="Y",$U35,1),$V35),"")) -> 0 | AE35: =IF($E35="","",IFERROR(IF($Q35>=$M35,1,0),0)) -> 0 | AG35: =IF($E35="","",IF($I35="Y",IFERROR($P35,0),1)) -> 0 | AH35: =IF($E35="","",IFERROR((Weights!$B$2*$O35 + Weights!$B$3*$AE35 + Weights!$B$4*$AD35 + Weights!$B$5*(1-$AC35) + Weights!$B$6*$AF35 + Weights!$B$7*$AG35)/SUM(Weights!$B$2:$B$7),"" )) -> 0.45 | AI35: =IF($E35="","",IF($O35=0,0,IFERROR($AH35/MAX(Weights!$B$8,$Y35)/MAX(Weights!$B$9,IF($Z35="",0,$Z35)), ""))) -> 0.0097465887
A36: 154501042026 | B36: 46026 | C36: Tavily | D36: JSON_API | E36: U043 | F36: =IF($E36="","",VLOOKUP($E36,Benchmark_URLs!$A$2:$L$46,4,FALSE)) -> https://search.worldbank.org/api/v2/news?format=json&rows=20&fct=displayconttype_exact,topic_exact,lang_exact,count_exact,countcode_exact,admreg_exact&src=cq55&apilang=en&lang_exact=English&displayconttype_exact=Press%20Release&os=0 | H36: =IF($E36="","",VLOOKUP($E36,Benchmark_URLs!$A$2:$L$46,6,FALSE)) -> json | I36: =IF($E36="","",VLOOKUP($E36,Benchmark_URLs!$A$2:$L$46,7,FALSE)) -> N | J36: =IF($E36="","",VLOOKUP($E36,Benchmark_URLs!$A$2:$L$46,8,FALSE)) -> N | K36: =IF($E36="","",VLOOKUP($E36,Benchmark_URLs!$A$2:$L$46,9,FALSE)) -> Y | L36: =IF($E36="","",VLOOKUP($E36,Benchmark_URLs!$A$2:$L$46,10,FALSE)) -> Y | M36: =IF($E36="","",VLOOKUP($E36,Benchmark_URLs!$A$2:$L$46,11,FALSE)) -> 1000 | N36: 200 | O36: 1 | P36: 0 | Q36: 0 | R36: 0 | S36: 0 | T36: 0 | U36: 0 | V36: 0 | W36: 0 | Y36: 4.09 | Z36: 3 | AB36: No Results Found | AC36: =IF($E36="","",IF($R36>0,MIN(1,$S36/$R36),"")) | AD36: =IF($E36="","",IFERROR(AVERAGE($T36,IF($L36="Y",$U36,1),$V36),"")) -> 0 | AE36: =IF($E36="","",IFERROR(IF($Q36>=$M36,1,0),0)) -> 0 | AG36: =IF($E36="","",IF($I36="Y",IFERROR($P36,0),1)) -> 1 | AH36: =IF($E36="","",IFERROR((Weights!$B$2*$O36 + Weights!$B$3*$AE36 + Weights!$B$4*$AD36 + Weights!$B$5*(1-$AC36) + Weights!$B$6*$AF36 + Weights!$B$7*$AG36)/SUM(Weights!$B$2:$B$7),"" )) -> 0.5 | AI36: =IF($E36="","",IF($O36=0,0,IFERROR($AH36/MAX(Weights!$B$8,$Y36)/MAX(Weights!$B$9,IF($Z36="",0,$Z36)), ""))) -> 0.040749796
A37: 154601042026 | B37: 46026 | C37: Tavily | D37: JSON_API | E37: U044 | F37: =IF($E37="","",VLOOKUP($E37,Benchmark_URLs!$A$2:$L$46,4,FALSE)) -> https://search.worldbank.org/api/v2/news?format=json&rows=20&fct=displayconttype_exact,topic_exact,lang_exact,count_exact,countcode_exact,admreg_exact&src=cq55&apilang=en&lang_exact=English&displayconttype_exact=Press%20Release&os=20 | H37: =IF($E37="","",VLOOKUP($E37,Benchmark_URLs!$A$2:$L$46,6,FALSE)) -> json | I37: =IF($E37="","",VLOOKUP($E37,Benchmark_URLs!$A$2:$L$46,7,FALSE)) -> N | J37: =IF($E37="","",VLOOKUP($E37,Benchmark_URLs!$A$2:$L$46,8,FALSE)) -> N | K37: =IF($E37="","",VLOOKUP($E37,Benchmark_URLs!$A$2:$L$46,9,FALSE)) -> Y | L37: =IF($E37="","",VLOOKUP($E37,Benchmark_URLs!$A$2:$L$46,10,FALSE)) -> Y | M37: =IF($E37="","",VLOOKUP($E37,Benchmark_URLs!$A$2:$L$46,11,FALSE)) -> 1000 | N37: 200 | O37: 1 | P37: 0 | Q37: 0 | R37: 0 | S37: 0 | T37: 0 | U37: 0 | V37: 0 | W37: 0 | Y37: 3.98 | Z37: 3 | AB37: No Results Found | AC37: =IF($E37="","",IF($R37>0,MIN(1,$S37/$R37),"")) | AD37: =IF($E37="","",IFERROR(AVERAGE($T37,IF($L37="Y",$U37,1),$V37),"")) -> 0 | AE37: =IF($E37="","",IFERROR(IF($Q37>=$M37,1,0),0)) -> 0 | AG37: =IF($E37="","",IF($I37="Y",IFERROR($P37,0),1)) -> 1 | AH37: =IF($E37="","",IFERROR((Weights!$B$2*$O37 + Weights!$B$3*$AE37 + Weights!$B$4*$AD37 + Weights!$B$5*(1-$AC37) + Weights!$B$6*$AF37 + Weights!$B$7*$AG37)/SUM(Weights!$B$2:$B$7),"" )) -> 0.5 | AI37: =IF($E37="","",IF($O37=0,0,IFERROR($AH37/MAX(Weights!$B$8,$Y37)/MAX(Weights!$B$9,IF($Z37="",0,$Z37)), ""))) -> 0.041876047
A38: 133001042026 | B38: 46026 | C38: Tavily | D38: Static_HTML | E38: U001 | F38: =IF($E38="","",VLOOKUP($E38,Benchmark_URLs!$A$2:$L$46,4,FALSE)) -> https://www.federalreserve.gov/supervisionreg.htm | H38: =IF($E38="","",VLOOKUP($E38,Benchmark_URLs!$A$2:$L$46,6,FALSE)) -> html | I38: =IF($E38="","",VLOOKUP($E38,Benchmark_URLs!$A$2:$L$46,7,FALSE)) -> N | J38: =IF($E38="","",VLOOKUP($E38,Benchmark_URLs!$A$2:$L$46,8,FALSE)) -> N | K38: =IF($E38="","",VLOOKUP($E38,Benchmark_URLs!$A$2:$L$46,9,FALSE)) -> N | L38: =IF($E38="","",VLOOKUP($E38,Benchmark_URLs!$A$2:$L$46,10,FALSE)) -> Y | M38: =IF($E38="","",VLOOKUP($E38,Benchmark_URLs!$A$2:$L$46,11,FALSE)) -> 4000 | N38: 200 | O38: 1 | P38: 0 | Q38: 6186 | R38: 8837 | S38: 1852 | T38: 1 | U38: 1 | V38: 0 | W38: 22 | Y38: 30.92 | Z38: 5 | AC38: =IF($E38="","",IF($R38>0,MIN(1,$S38/$R38),"")) -> 0.20957338 | AD38: =IF($E38="","",IFERROR(AVERAGE($T38,IF($L38="Y",$U38,1),$V38),"")) -> 0.66666667 | AE38: =IF($E38="","",IFERROR(IF($Q38>=$M38,1,0),0)) -> 1 | AG38: =IF($E38="","",IF($I38="Y",IFERROR($P38,0),1)) -> 1 | AH38: =IF($E38="","",IFERROR((Weights!$B$2*$O38 + Weights!$B$3*$AE38 + Weights!$B$4*$AD38 + Weights!$B$5*(1-$AC38) + Weights!$B$6*$AF38 + Weights!$B$7*$AG38)/SUM(Weights!$B$2:$B$7),"" )) -> 0.81856399 | AI38: =IF($E38="","",IF($O38=0,0,IFERROR($AH38/MAX(Weights!$B$8,$Y38)/MAX(Weights!$B$9,IF($Z38="",0,$Z38)), ""))) -> 0.0052947218
A39: 171701042026 | B39: 46026 | C39: Parallel | D39: Static_HTML | E39: U001 | F39: =IF($E39="","",VLOOKUP($E39,Benchmark_URLs!$A$2:$L$46,4,FALSE)) -> https://www.federalreserve.gov/supervisionreg.htm | H39: =IF($E39="","",VLOOKUP($E39,Benchmark_URLs!$A$2:$L$46,6,FALSE)) -> html | I39: =IF($E39="","",VLOOKUP($E39,Benchmark_URLs!$A$2:$L$46,7,FALSE)) -> N | J39: =IF($E39="","",VLOOKUP($E39,Benchmark_URLs!$A$2:$L$46,8,FALSE)) -> N | K39: =IF($E39="","",VLOOKUP($E39,Benchmark_URLs!$A$2:$L$46,9,FALSE)) -> N | L39: =IF($E39="","",VLOOKUP($E39,Benchmark_URLs!$A$2:$L$46,10,FALSE)) -> Y | M39: =IF($E39="","",VLOOKUP($E39,Benchmark_URLs!$A$2:$L$46,11,FALSE)) -> 4000 | N39: 200 | O39: 1 | P39: 0 | Q39: 9800 | R39: 9800 | S39: 0 | T39: 1 | U39: 1 | V39: 0 | W39: 0 | Y39: 1.07 | Z39: 1 | AB39: Extraction OK; warning says objective/search_queries missing (relevance tuning), but page content still correct | AC39: =IF($E39="","",IF($R39>0,MIN(1,$S39/$R39),"")) -> 0 | AD39: =IF($E39="","",IFERROR(AVERAGE($T39,IF($L39="Y",$U39,1),$V39),"")) -> 0.66666667 | AE39: =IF($E39="","",IFERROR(IF($Q39>=$M39,1,0),0)) -> 1 | AG39: =IF($E39="","",IF($I39="Y",IFERROR($P39,0),1)) -> 1 | AH39: =IF($E39="","",IFERROR((Weights!$B$2*$O39 + Weights!$B$3*$AE39 + Weights!$B$4*$AD39 + Weights!$B$5*(1-$AC39) + Weights!$B$6*$AF39 + Weights!$B$7*$AG39)/SUM(Weights!$B$2:$B$7),"" )) -> 0.85 | AI39: =IF($E39="","",IF($O39=0,0,IFERROR($AH39/MAX(Weights!$B$8,$Y39)/MAX(Weights!$B$9,IF($Z39="",0,$Z39)), ""))) -> 0.79439252
